Workbook

Sheet anexa2_1 Resurse
A1: Alocarea resurselor pe activități (resursele umane din echipa proiectului vor fi introduse conform alocarii din Anexa 1 - Graficul Responsabilitatilor)
A3: Cod activitate | B3: Denumire activitate | C3: Denumire resursă | D3: Unitate de măsură | E3: Cantitate estimată necesară | F3: Preț pe unitate | G3: Valoare | H3: Nume student
A4: 1000 | B4: Analiza și Planificarea inițială | C4: - | D4: - | E4: - | F4: - | G4: - | H4: Ciobanu Rareș
A5: 1100 | B5: Analiza proceselor interne actuale (as-is) | C5: Expertiză Tehnică (Ciobanu Rareș) | D5: ore | E5: 20 | F5: 50 | G5: 1000 | H5: Ciobanu Rareș
C6: Consumabile birou (hârtie, toner) | D6: set | E6: 1 | F6: 200 | G6: 200 | H6: Ciobanu Rareș
A7: 1200 | B7: Definirea fluxurilor dorite (to-be) | C7: Expertiză Tehnică (Ciobanu Rareș) | D7: ore | E7: 20 | F7: 50 | G7: 1000 | H7: Ciobanu Rareș
A8: 1300 | B8: Elaborarea specificațiilor tehnice | C8: Expertiză Tehnică (Ciobanu Rareș) | D8: ore | E8: 20 | F8: 50 | G8: 1000 | H8: Ciobanu Rareș
A9: 1400 | B9: Redactarea Caietului de Sarcini | C9: Expertiză Tehnică (Ciobanu Rareș) | D9: ore | E9: 20 | F9: 50 | G9: 1000 | H9: Ciobanu Rareș
A10: 2000 | B10: Achiziția serviciilor de dezvoltare | C10: - | D10: - | E10: - | F10: - | G10: - | H10: Lupu Raluca
A11: 2100 | B11: Prospectarea pieței furnizorilor | C11: Expertiză Achiziții (Lupu Raluca) | D11: ore | E11: 15 | F11: 50 | G11: 750 | H11: Lupu Raluca
C12: Abonament platformă licitații publice | D12: buc | E12: 1 | F12: 500 | G12: 500 | H12: Lupu Raluca
A13: 2200 | B13: Transmiterea Cererilor de Ofertă (RFO) | C13: Expertiză Achiziții (Lupu Raluca) | D13: ore | E13: 15 | F13: 50 | G13: 750 | H13: Lupu Raluca
A14: 2300 | B14: Evaluarea ofertelor | C14: Expertiză Achiziții (Lupu Raluca) | D14: ore | E14: 15 | F14: 50 | G14: 750 | H14: Lupu Raluca
A15: 2400 | B15: Negocierea și semnarea contractului | C15: Expertiză Achiziții (Lupu Raluca) | D15: ore | E15: 15 | F15: 50 | G15: 750 | H15: Lupu Raluca
A16: 3000 | B16: Dezvoltarea și Integrarea Platformei | C16: - | D16: - | E16: - | F16: - | G16: - | H16: Păun Marius
A17: 3100 | B17: Configurare servere și mediu dev. | C17: Expertiză Manager Proiect (Păun M.) | D17: ore | E17: 30 | F17: 60 | G17: 1800 | H17: Păun Marius
C18: Server Hosting Dedicat (1 an) | D18: buc | E18: 1 | F18: 4500 | G18: 4500 | H18: Păun Marius
C19: Certificat SSL EV | D19: buc | E19: 1 | F19: 800 | G19: 800 | H19: Păun Marius
A20: 3200 | B20: Dezvoltarea conectorului API | C20: Expertiză Manager Proiect (Păun M.) | D20: ore | E20: 40 | F20: 60 | G20: 2400 | H20: Păun Marius
C21: Servicii Dezvoltare Soft (Tranșa 1) | D21: contr. | E21: 0.5 | F21: 85000 | G21: 42500 | H21: Păun Marius
A22: 3300 | B22: Implementare design și funcționalități | C22: Expertiză Manager Proiect (Păun M.) | D22: ore | E22: 40 | F22: 60 | G22: 2400 | H22: Păun Marius
C23: Servicii Dezvoltare Soft (Tranșa 2) | D23: contr. | E23: 0.5 | F23: 85000 | G23: 42500 | H23: Păun Marius
A24: 3400 | B24: Testarea funcțională și securitate | C24: Expertiză Manager Proiect (Păun M.) | D24: ore | E24: 10 | F24: 60 | G24: 600 | H24: Păun Marius
A25: 4000 | B25: Gestionarea Conținutului | C25: - | D25: - | E25: - | F25: - | G25: - | H25: Ciobanu Rareș
A26: 4100 | B26: Colectarea specificațiilor și foto | C26: Expertiză Conținut (Ciobanu Rareș) | D26: ore | E26: 100 | F26: 50 | G26: 5000 | H26: Ciobanu Rareș
C27: HDD Extern 4TB Backup | D27: buc | E27: 2 | F27: 400 | G27: 800 | H27: Ciobanu Rareș
A28: 4200 | B28: Prelucrarea imaginilor de produs | C28: Expertiză Conținut (Ciobanu Rareș) | D28: ore | E28: 40 | F28: 50 | G28: 2000 | H28: Ciobanu Rareș
C29: Licență Adobe Photoshop/Lightroom | D29: buc | E29: 1 | F29: 1200 | G29: 1200 | H29: Ciobanu Rareș
A30: 4300 | B30: Importul datelor și verificare (QA) | C30: Expertiză Conținut (Ciobanu Rareș) | D30: ore | E30: 20 | F30: 50 | G30: 1000 | H30: Ciobanu Rareș
A31: 5000 | B31: Management Resurse Umane | C31: - | D31: - | E31: - | F31: - | G31: - | H31: Lupu Raluca
A32: 5100 | B32: Elaborarea materialelor de training | C32: Expertiză Trainer (Lupu Raluca) | D32: ore | E32: 15 | F32: 50 | G32: 750 | H32: Lupu Raluca
C33: Materiale training printate | D33: buc | E33: 15 | F33: 30 | G33: 450 | H33: Lupu Raluca
A34: 5200 | B34: Susținerea sesiunilor de training | C34: Expertiză Trainer (Lupu Raluca) | D34: ore | E34: 15 | F34: 50 | G34: 750 | H34: Lupu Raluca
C35: Protocol sesiuni (apă, cafea) | D35: pachet | E35: 1 | F35: 300 | G35: 300 | H35: Lupu Raluca
A36: 5300 | B36: Evaluarea cunoștințelor dobândite | C36: Expertiză Trainer (Lupu Raluca) | D36: ore | E36: 10 | F36: 50 | G36: 500 | H36: Lupu Raluca
A37: 6000 | B37: Lansare și Monitorizare Proiect | C37: - | D37: - | E37: - | F37: - | G37: - | H37: Păun Marius
A38: 6100 | B38: Monitorizarea progresului (recurent) | C38: Expertiză Manager Proiect (Păun M.) | D38: ore | E38: 60 | F38: 60 | G38: 3600 | H38: Păun Marius
A39: 6200 | B39: Campanie de marketing lansare | C39: Expertiză Manager Proiect (Păun M.) | D39: ore | E39: 20 | F39: 60 | G39: 1200 | H39: Păun Marius
C40: Campanie Marketing Online (Ads) | D40: camp. | E40: 1 | F40: 5000 | G40: 5000 | H40: Păun Marius
C41: Servicii Grafică Promo | D41: pachet | E41: 1 | F41: 1500 | G41: 1500 | H41: Păun Marius
...

Sheet anexa2_2 Buget_detaliat
A1: Buget detaliat pe categorii de cheltuieli
A3: Denumire solicitant fonduri: | B3: Costuri totale | G3: 1. Denumirile resurselor de pe prima coloană vor fi aceleași cu cele identificate pe activități
A4: SC NextGen Hardware SRL | B4: Unitatea de măsură | C4: Numărul de unitați | D4: Cost pe unitate | E4: Cost total | G4: (4.1 în formularul de proiect, anexa 2_1resurse), dar aici sunt sortate în funcție de tipul de cheltuială pe care o generează.
A5: Moneda:
A6: RON | G6: 2. Se pot adăuga linii dacă este nevoie. În acest caz, va fi necesară refacerea formulelor din anexa 2_3buget_general.
A8: Cheltuieli cu personalul | B8: lună, zi sau oră
A9: Manager de proiect (Păun Marius) | B9: ore | C9: 220 | D9: 60 | E9: 13200
A10: Membru echipă 1 (Ciobanu Rareș - Coord. Tehnic) | B10: ore | C10: 240 | D10: 50 | E10: 12000
A11: Membru echipă 2 (Lupu Raluca - Coord. Achiziții) | B11: ore | C11: 100 | D11: 50 | E11: 5000
A12: Total cheltuieli cu personalul | E12: =SUM(E9:E11) -> 30200
A14: Cheltuieli cu consultanță/servicii | B14: lună, zi sau oră; contravaloare serviciu de oferire expertiză/consultanță
A15: (Nu avem consultanți externi în afara contractului mare de la investiții) | E15: =C15*D15 -> 0
A16: Total cheltuieli consultanță/servicii | E16: =SUM(E15:E15) -> 0
A18: Cheltuieli cu investițiile în spații (amenajări spații, clădiri etc.) | B18: mp, deviz lucrare etc.
A19: ... | E19: =C19*D19 -> 0
A20: Total cheltuieli investițiile în spații (amenajări) | E20: =SUM(E19:E19) -> 0
A22: Cheltuieli cu investițiile în mobilier | B22: bucată etc.
A23: ... | E23: =C23*D23 -> 0
A24: Total cheltuieli cu investițiile în mobilier | E24: =SUM(E23:E23) -> 0
A26: Cheltuieli cu investițiile în echipamente | B26: bucată etc.
A27: HDD Extern 4TB pentru Backup date | B27: buc | C27: 2 | D27: 400 | E27: 800
A28: Total cheltuieli cu investițiile în echipamente | E28: =SUM(E27:E27) -> 800
A30: Cheltuieli cu investițiile în software | B30: bucată, licență pe produs, licență anuală etc.
A31: Contract Prestări Servicii Dezvoltare Software | B31: contract | C31: 1 | D31: 85000 | E31: 85000
A32: Abonament Server Hosting Dedicat (1 an) | B32: buc | C32: 1 | D32: 4500 | E32: 4500
A33: Certificat SSL EV (Extended Validation) | B33: buc | C33: 1 | D33: 800 | E33: 800
A34: Licență Adobe Photoshop/Lightroom | B34: buc | C34: 1 | D34: 1200 | E34: 1200
A35: Total cheltuieli cu investițiile în software | E35: =SUM(E31:E34) -> 91500
A37: Cheltuieli materiale (materiale consumabile) | B37: l, m, bucăți, kg etc.
A38: Consumabile birou (hârtie, toner) | B38: set | C38: 1 | D38: 200 | E38: 200
A39: Materiale training printate (manuale) | B39: buc | C39: 15 | D39: 30 | E39: 450
A40: Pachet protocol sesiuni training (apă, cafea) | B40: pachet | C40: 1 | D40: 300 | E40: 300
A41: Total cheltuieli materiale consumabile | E41: =SUM(E38:E40) -> 950
A43: Cheltuieli cu chiriile | B43: mp/lună, mp/an, an, bucată/zi, bucată/an etc.
A44: … | E44: =C44*D44 -> 0
A45: Total cheltuieli cu chiriile | E45: =SUM(E44:E44) -> 0
A47: Cheltuieli cu resursele informaționale | B47: bucăți, abonament pe an etc.
A48: Abonament platformă licitații publice | B48: buc | C48: 1 | D48: 500 | E48: 500
A49: Total cheltuieli cu resursele informaționale | E49: =SUM(E48:E48) -> 500
A51: Cheltuieli promoționale | B51: minute, bucăți etc.
...

Sheet anexa2_3 Buget_general
A1: Buget general
A3: Denumire solicitant fonduri: | B3: Cost total | C3: Sursa de finanțare
C4: Contribuție finanțator | D4: Contribuție proprie
A5: Moneda:
A7: A. Cheltuieli de exploatare
A8: ='anexa2_2 Buget_detaliat'!A8 -> Cheltuieli cu personalul | B8: ='anexa2_2 Buget_detaliat'!E12 -> 30200 | D8: 30200
A9: ='anexa2_2 Buget_detaliat'!A14 -> Cheltuieli cu consultanță/servicii | B9: ='anexa2_2 Buget_detaliat'!E16 -> 0 | D9: 0
A10: ='anexa2_2 Buget_detaliat'!A37 -> Cheltuieli materiale (materiale consumabile) | B10: ='anexa2_2 Buget_detaliat'!E41 -> 950 | D10: 950
A11: Cheltuieli cu chiriile | B11: ='anexa2_2 Buget_detaliat'!E45 -> 0 | D11: 0
A12: ='anexa2_2 Buget_detaliat'!A47 -> Cheltuieli cu resursele informaționale | B12: ='anexa2_2 Buget_detaliat'!E49 -> 500 | D12: 500
A13: ='anexa2_2 Buget_detaliat'!A51 -> Cheltuieli promoționale | B13: ='anexa2_2 Buget_detaliat'!E54 -> 6500 | D13: 6500
A14: ='anexa2_2 Buget_detaliat'!A56 -> Cheltuieli cu mobilitățile și transportul | B14: ='anexa2_2 Buget_detaliat'!E58 -> 0 | D14: 0
A15: ='anexa2_2 Buget_detaliat'!A60 -> Cheltuieli curente | B15: ='anexa2_2 Buget_detaliat'!E62 -> 0 | D15: 0
A16: ='anexa2_2 Buget_detaliat'!A64 -> Alte cheltuieli | B16: ='anexa2_2 Buget_detaliat'!E66 -> 0 | D16: 0
A17: Cheltuieli speciale | B17: 0 | D17: 0
A18: Cheltuieli neprevăzute | B18: 0 | D18: 0
A19: Subtotal cheltuieli de exploatare (A) | B19: =SUM(B8:B18) -> 38150 | C19: =SUM(C8:C18) -> 0 | D19: =SUM(D8:D18) -> 38150
A20: B. Investiții
A21: ='anexa2_2 Buget_detaliat'!A18 -> Cheltuieli cu investițiile în spații (amenajări spații, clădiri etc.) | B21: ='anexa2_2 Buget_detaliat'!E20 -> 0 | D21: 0
A22: ='anexa2_2 Buget_detaliat'!A22 -> Cheltuieli cu investițiile în mobilier | B22: ='anexa2_2 Buget_detaliat'!E24 -> 0 | D22: 0
A23: ='anexa2_2 Buget_detaliat'!A26 -> Cheltuieli cu investițiile în echipamente | B23: ='anexa2_2 Buget_detaliat'!E28 -> 800 | D23: 800
A24: ='anexa2_2 Buget_detaliat'!A30 -> Cheltuieli cu investițiile în software | B24: ='anexa2_2 Buget_detaliat'!E35 -> 91500 | D24: 91500
A25: Subtotal investiții (B) | B25: =SUM(B21:B24) -> 92300 | C25: =SUM(C21:C24) -> 0 | D25: =SUM(D21:D24) -> 92300
A26: TOTAL BUGET | B26: =B19+B25 -> 130450 | C26: =C19+C25 -> 0 | D26: =D19+D25 -> 130450
